2019-10-18 11:11:14,026 INFO: Microblog startup [in /home/pablo/Escritorio/Practicas/microblog/app/__init__.py:43
2019-10-18 11:11:41,659 INFO: Microblog startup [in /home/pablo/Escritorio/Practicas/microblog/app/__init__.py:43
2019-10-18 11:11:48,410 ERROR: Exception on /register [POST] [in /home/pablo/Escritorio/Practicas/microblog/venv/lib/python3.6/site-packages/flask/app.py:1891
Traceback (most recent call last):
  File "/home/pablo/Escritorio/Practicas/microblog/venv/lib/python3.6/site-packages/sqlalchemy/engine/base.py", line 1249, in _execute_context
    cursor, statement, parameters, context
  File "/home/pablo/Escritorio/Practicas/microblog/venv/lib/python3.6/site-packages/sqlalchemy/engine/default.py", line 552, in do_execute
    cursor.execute(statement, parameters)
sqlite3.IntegrityError: UNIQUE constraint failed: user.username

The above exception was the direct cause of the following exception:

Traceback (most recent call last):
  File "/home/pablo/Escritorio/Practicas/microblog/venv/lib/python3.6/site-packages/flask/app.py", line 2446, in wsgi_app
    response = self.full_dispatch_request()
  File "/home/pablo/Escritorio/Practicas/microblog/venv/lib/python3.6/site-packages/flask/app.py", line 1951, in full_dispatch_request
    rv = self.handle_user_exception(e)
  File "/home/pablo/Escritorio/Practicas/microblog/venv/lib/python3.6/site-packages/flask/app.py", line 1820, in handle_user_exception
    reraise(exc_type, exc_value, tb)
  File "/home/pablo/Escritorio/Practicas/microblog/venv/lib/python3.6/site-packages/flask/_compat.py", line 39, in reraise
    raise value
  File "/home/pablo/Escritorio/Practicas/microblog/venv/lib/python3.6/site-packages/flask/app.py", line 1949, in full_dispatch_request
    rv = self.dispatch_request()
  File "/home/pablo/Escritorio/Practicas/microblog/venv/lib/python3.6/site-packages/flask/app.py", line 1935, in dispatch_request
    return self.view_functions[rule.endpoint](**req.view_args)
  File "/home/pablo/Escritorio/Practicas/microblog/app/routes.py", line 45, in register
    db.session.commit()
  File "/home/pablo/Escritorio/Practicas/microblog/venv/lib/python3.6/site-packages/sqlalchemy/orm/scoping.py", line 162, in do
    return getattr(self.registry(), name)(*args, **kwargs)
  File "/home/pablo/Escritorio/Practicas/microblog/venv/lib/python3.6/site-packages/sqlalchemy/orm/session.py", line 1027, in commit
    self.transaction.commit()
  File "/home/pablo/Escritorio/Practicas/microblog/venv/lib/python3.6/site-packages/sqlalchemy/orm/session.py", line 494, in commit
    self._prepare_impl()
  File "/home/pablo/Escritorio/Practicas/microblog/venv/lib/python3.6/site-packages/sqlalchemy/orm/session.py", line 473, in _prepare_impl
    self.session.flush()
  File "/home/pablo/Escritorio/Practicas/microblog/venv/lib/python3.6/site-packages/sqlalchemy/orm/session.py", line 2459, in flush
    self._flush(objects)
  File "/home/pablo/Escritorio/Practicas/microblog/venv/lib/python3.6/site-packages/sqlalchemy/orm/session.py", line 2597, in _flush
    transaction.rollback(_capture_exception=True)
  File "/home/pablo/Escritorio/Practicas/microblog/venv/lib/python3.6/site-packages/sqlalchemy/util/langhelpers.py", line 68, in __exit__
    compat.reraise(exc_type, exc_value, exc_tb)
  File "/home/pablo/Escritorio/Practicas/microblog/venv/lib/python3.6/site-packages/sqlalchemy/util/compat.py", line 153, in reraise
    raise value
  File "/home/pablo/Escritorio/Practicas/microblog/venv/lib/python3.6/site-packages/sqlalchemy/orm/session.py", line 2557, in _flush
    flush_context.execute()
  File "/home/pablo/Escritorio/Practicas/microblog/venv/lib/python3.6/site-packages/sqlalchemy/orm/unitofwork.py", line 422, in execute
    rec.execute(self)
  File "/home/pablo/Escritorio/Practicas/microblog/venv/lib/python3.6/site-packages/sqlalchemy/orm/unitofwork.py", line 589, in execute
    uow,
  File "/home/pablo/Escritorio/Practicas/microblog/venv/lib/python3.6/site-packages/sqlalchemy/orm/persistence.py", line 245, in save_obj
    insert,
  File "/home/pablo/Escritorio/Practicas/microblog/venv/lib/python3.6/site-packages/sqlalchemy/orm/persistence.py", line 1138, in _emit_insert_statements
    statement, params
  File "/home/pablo/Escritorio/Practicas/microblog/venv/lib/python3.6/site-packages/sqlalchemy/engine/base.py", line 988, in execute
    return meth(self, multiparams, params)
  File "/home/pablo/Escritorio/Practicas/microblog/venv/lib/python3.6/site-packages/sqlalchemy/sql/elements.py", line 287, in _execute_on_connection
    return connection._execute_clauseelement(self, multiparams, params)
  File "/home/pablo/Escritorio/Practicas/microblog/venv/lib/python3.6/site-packages/sqlalchemy/engine/base.py", line 1107, in _execute_clauseelement
    distilled_params,
  File "/home/pablo/Escritorio/Practicas/microblog/venv/lib/python3.6/site-packages/sqlalchemy/engine/base.py", line 1253, in _execute_context
    e, statement, parameters, cursor, context
  File "/home/pablo/Escritorio/Practicas/microblog/venv/lib/python3.6/site-packages/sqlalchemy/engine/base.py", line 1473, in _handle_dbapi_exception
    util.raise_from_cause(sqlalchemy_exception, exc_info)
  File "/home/pablo/Escritorio/Practicas/microblog/venv/lib/python3.6/site-packages/sqlalchemy/util/compat.py", line 398, in raise_from_cause
    reraise(type(exception), exception, tb=exc_tb, cause=cause)
  File "/home/pablo/Escritorio/Practicas/microblog/venv/lib/python3.6/site-packages/sqlalchemy/util/compat.py", line 152, in reraise
    raise value.with_traceback(tb)
  File "/home/pablo/Escritorio/Practicas/microblog/venv/lib/python3.6/site-packages/sqlalchemy/engine/base.py", line 1249, in _execute_context
    cursor, statement, parameters, context
  File "/home/pablo/Escritorio/Practicas/microblog/venv/lib/python3.6/site-packages/sqlalchemy/engine/default.py", line 552, in do_execute
    cursor.execute(statement, parameters)
sqlalchemy.exc.IntegrityError: (sqlite3.IntegrityError) UNIQUE constraint failed: user.username
[SQL: INSERT INTO user (username, email, password_hash, about_me, last_seen) VALUES (?, ?, ?, ?, ?)]
[parameters: ('Pepe', 'pepe@pepe.com', 'pbkdf2:sha256:150000$LJdOLQLD$334972199f6d51e2042f4f72fb1d029f247d4181717b8e6fd0c6dac769cdaefb', None, '2019-10-18 14:11:48.409722')]
(Background on this error at: http://sqlalche.me/e/gkpj)
2019-10-18 11:44:23,684 INFO: Microblog startup [in /home/pablo/Escritorio/Practicas/microblog/app/__init__.py:44
2019-10-18 11:44:38,973 INFO: Microblog startup [in /home/pablo/Escritorio/Practicas/microblog/app/__init__.py:44
